HTTP/1.1 500 Internal Server Error
Content-Type: application/json

{
    "message": "'NoneType' object has no attribute 'form_instance'",
    "traceback": [
        "File \"/tmp/plone.restapi/eggs/Zope-4.6.3-py3.8.egg/ZPublisher/WSGIPublisher.py\", line 162, in transaction_pubevents",
        "    yield",
        "",
        "  File \"/tmp/plone.restapi/eggs/Zope-4.6.3-py3.8.egg/ZPublisher/WSGIPublisher.py\", line 371, in publish_module",
        "    response = _publish(request, new_mod_info)",
        "",
        "  File \"/tmp/plone.restapi/eggs/Zope-4.6.3-py3.8.egg/ZPublisher/WSGIPublisher.py\", line 266, in publish",
        "    result = mapply(obj,",
        "",
        "  File \"/tmp/plone.restapi/eggs/Zope-4.6.3-py3.8.egg/ZPublisher/mapply.py\", line 85, in mapply",
        "    return debug(object, args, context)",
        "",
        "  File \"/tmp/plone.restapi/eggs/Zope-4.6.3-py3.8.egg/ZPublisher/WSGIPublisher.py\", line 63, in call_object",
        "    return obj(*args)",
        "",
        "  File \"/tmp/plone.restapi/eggs/plone.rest-2.0.0a3-py3.8.egg/plone/rest/service.py\", line 22, in __call__",
        "    return self.render()",
        "",
        "  File \"/tmp/plone.restapi/src/plone/restapi/services/__init__.py\", line 19, in render",
        "    content = self.reply()",
        "",
        "  File \"/tmp/plone.restapi/src/plone/restapi/services/controlpanels/get.py\", line 46, in reply",
        "    return self.reply_panel()",
        "",
        "  File \"/tmp/plone.restapi/src/plone/restapi/services/controlpanels/get.py\", line 66, in reply_panel",
        "    return IJsonCompatible(panel.get(self.params[1:]))",
        "",
        "  File \"/tmp/plone.restapi/src/plone/restapi/controlpanels/rules.py\", line 90, in get",
        "    view.form_instance.update()"
    ],
    "type": "AttributeError"
}
