HTTP/1.1 500 Internal Server Error
Content-Type: application/json

{
    "message": "<PloneSite at /plone>",
    "traceback": [
        "File \"/Users/katjasuss/Volto/sandbox/backend/src/plone.restapi/eggs/Zope-5.5.1-py3.9.egg/ZPublisher/WSGIPublisher.py\", line 167, in transaction_pubevents",
        "    yield",
        "",
        "  File \"/Users/katjasuss/Volto/sandbox/backend/src/plone.restapi/eggs/Zope-5.5.1-py3.9.egg/ZPublisher/WSGIPublisher.py\", line 376, in publish_module",
        "    response = _publish(request, new_mod_info)",
        "",
        "  File \"/Users/katjasuss/Volto/sandbox/backend/src/plone.restapi/eggs/Zope-5.5.1-py3.9.egg/ZPublisher/WSGIPublisher.py\", line 271, in publish",
        "    result = mapply(obj,",
        "",
        "  File \"/Users/katjasuss/Volto/sandbox/backend/src/plone.restapi/eggs/Zope-5.5.1-py3.9.egg/ZPublisher/mapply.py\", line 85, in mapply",
        "    return debug(object, args, context)",
        "",
        "  File \"/Users/katjasuss/Volto/sandbox/backend/src/plone.restapi/eggs/Zope-5.5.1-py3.9.egg/ZPublisher/WSGIPublisher.py\", line 68, in call_object",
        "    return obj(*args)",
        "",
        "  File \"/Users/katjasuss/Volto/sandbox/backend/src/plone.restapi/eggs/plone.rest-2.0.0a5-py3.9.egg/plone/rest/service.py\", line 22, in __call__",
        "    return self.render()",
        "",
        "  File \"/Users/katjasuss/Volto/sandbox/backend/src/plone.restapi/src/plone/restapi/services/__init__.py\", line 19, in render",
        "    content = self.reply()",
        "",
        "  File \"/Users/katjasuss/Volto/sandbox/backend/src/plone.restapi/src/plone/restapi/services/relations/get.py\", line 127, in reply",
        "    data = get_relations(",
        "",
        "  File \"/Users/katjasuss/Volto/sandbox/backend/src/plone.restapi/src/plone/restapi/services/relations/get.py\", line 39, in get_relations",
        "    query[\"from_id\"] = intids.getId(source)",
        "",
        "  File \"/Users/katjasuss/Volto/sandbox/backend/src/plone.restapi/eggs/five.intid-1.2.6-py3.9.egg/five/intid/intid.py\", line 43, in getId",
        "    return z3IntIds.getId(self, ob)",
        "",
        "  File \"/Users/katjasuss/Volto/sandbox/backend/src/plone.restapi/eggs/zope.intid-4.4.0-py3.9.egg/zope/intid/__init__.py\", line 108, in getId",
        "    raise IntIdMissingError(ob)"
    ],
    "type": "IntIdMissingError"
}
